Workbook

Sheet Resumen
A1: AG Supply: pendientes del sitio y de Google
A2: Estado del sitio: publicado en https://agsupply.com.do. Lo que sigue depende de fotos, datos del cliente, correcciones en Odoo y pasos en Google.
A4: Hoja | B4: Qué contiene | C4: Filas | D4: Pendientes | E4: Entregadas | F4: % avance
A5: 1 Fotos de producto | B5: 135 fotos de producto con qué mostrar, medidas y archivo | C5: =COUNTA('1 Fotos de producto'!$M$5:$M$139) -> 135 | D5: =COUNTIF('1 Fotos de producto'!$M$5:$M$139,"Pendiente")+COUNTIF('1 Fotos de producto'!$M$5:$M$139,"En curso") -> 135 | E5: =COUNTIF('1 Fotos de producto'!$M$5:$M$139,"Entregado") -> 0 | F5: =IF((C5-COUNTIF('1 Fotos de producto'!$M$5:$M$139,"No aplica"))=0,0,E5/(C5-COUNTIF('1 Fotos de producto'!$M$5:$M$139,"No aplica"))) -> 0
A6: 2 Fotos existentes | B6: Fotos ya publicadas que conviene re-tomar | C6: =COUNTA('2 Fotos existentes'!$H$5:$H$37) -> 33 | D6: =COUNTIF('2 Fotos existentes'!$H$5:$H$37,"Pendiente")+COUNTIF('2 Fotos existentes'!$H$5:$H$37,"En curso") -> 22 | E6: =COUNTIF('2 Fotos existentes'!$H$5:$H$37,"Entregado") -> 0 | F6: =IF((C6-COUNTIF('2 Fotos existentes'!$H$5:$H$37,"No aplica"))=0,0,E6/(C6-COUNTIF('2 Fotos existentes'!$H$5:$H$37,"No aplica"))) -> 0
A7: 3 Fotos del sitio | B7: Planta, marcas y fachada | C7: =COUNTA('3 Fotos del sitio'!$K$5:$K$15) -> 11 | D7: =COUNTIF('3 Fotos del sitio'!$K$5:$K$15,"Pendiente")+COUNTIF('3 Fotos del sitio'!$K$5:$K$15,"En curso") -> 11 | E7: =COUNTIF('3 Fotos del sitio'!$K$5:$K$15,"Entregado") -> 0 | F7: =IF((C7-COUNTIF('3 Fotos del sitio'!$K$5:$K$15,"No aplica"))=0,0,E7/(C7-COUNTIF('3 Fotos del sitio'!$K$5:$K$15,"No aplica"))) -> 0
A8: 4 Logos y marca | B8: Logos vectoriales, iconos y colores oficiales | C8: =COUNTA('4 Logos y marca'!$H$5:$H$12) -> 8 | D8: =COUNTIF('4 Logos y marca'!$H$5:$H$12,"Pendiente")+COUNTIF('4 Logos y marca'!$H$5:$H$12,"En curso") -> 8 | E8: =COUNTIF('4 Logos y marca'!$H$5:$H$12,"Entregado") -> 0 | F8: =IF((C8-COUNTIF('4 Logos y marca'!$H$5:$H$12,"No aplica"))=0,0,E8/(C8-COUNTIF('4 Logos y marca'!$H$5:$H$12,"No aplica"))) -> 0
A9: 5 Datos del cliente | B9: Información que solo el cliente puede dar | C9: =COUNTA('5 Datos del cliente'!$F$5:$F$24) -> 20 | D9: =COUNTIF('5 Datos del cliente'!$F$5:$F$24,"Pendiente")+COUNTIF('5 Datos del cliente'!$F$5:$F$24,"En curso") -> 20 | E9: =COUNTIF('5 Datos del cliente'!$F$5:$F$24,"Entregado") -> 0 | F9: =IF((C9-COUNTIF('5 Datos del cliente'!$F$5:$F$24,"No aplica"))=0,0,E9/(C9-COUNTIF('5 Datos del cliente'!$F$5:$F$24,"No aplica"))) -> 0
A10: 6 Odoo (catálogo) | B10: Correcciones de SKU y datos en Odoo | C10: =COUNTA('6 Odoo (catálogo)'!$F$5:$F$73) -> 69 | D10: =COUNTIF('6 Odoo (catálogo)'!$F$5:$F$73,"Pendiente")+COUNTIF('6 Odoo (catálogo)'!$F$5:$F$73,"En curso") -> 69 | E10: =COUNTIF('6 Odoo (catálogo)'!$F$5:$F$73,"Entregado") -> 0 | F10: =IF((C10-COUNTIF('6 Odoo (catálogo)'!$F$5:$F$73,"No aplica"))=0,0,E10/(C10-COUNTIF('6 Odoo (catálogo)'!$F$5:$F$73,"No aplica"))) -> 0
A11: 7 Técnico y Google | B11: Search Console, Analytics, Maps, despliegue | C11: =COUNTA('7 Técnico y Google'!$G$5:$G$20) -> 16 | D11: =COUNTIF('7 Técnico y Google'!$G$5:$G$20,"Pendiente")+COUNTIF('7 Técnico y Google'!$G$5:$G$20,"En curso") -> 16 | E11: =COUNTIF('7 Técnico y Google'!$G$5:$G$20,"Entregado") -> 0 | F11: =IF((C11-COUNTIF('7 Técnico y Google'!$G$5:$G$20,"No aplica"))=0,0,E11/(C11-COUNTIF('7 Técnico y Google'!$G$5:$G$20,"No aplica"))) -> 0
A12: Total | C12: =SUM(C5:C11) -> 292 | D12: =SUM(D5:D11) -> 281 | E12: =SUM(E5:E11) -> 0 | F12: =IF(C12=0,0,E12/C12) -> 0
A14: Cómo usar este libro
A15: 1. Cada hoja es una lista de trabajo. Cambia la columna «Estado» con el menú desplegable (Pendiente, En curso, Entregado, No aplica): esta hoja se actualiza sola.
A16: 2. Las columnas «Notas» y «Respuesta del cliente» son para escribir libremente. No hace falta tocar las demás.
A17: 3. Las medidas de las fotos son recomendaciones para que todo el catálogo se vea uniforme. Están resumidas en la hoja «Especificaciones».
A18: 4. Prioridad «Alta» = afecta al SEO, a la confianza del sitio o bloquea otra tarea. La hoja 1 sombrea las 55 fichas que hoy están en noindex.
A19: 5. Las cantidades (135 fotos, 55 fichas, 258 URLs) salen de content/products.json y del sitemap publicado al 26 de octubre de 2026.

Sheet Especificaciones
A1: Especificaciones de entrega de imágenes
A3: FOTO DE PRODUCTO
A4: Medida | B4: 1200 × 1200 px (1:1). Mínimo aceptable: 900 × 900 px. No entregar menos.
A5: Fondo | B5: Blanco puro (#FFFFFF), liso, sin degradados ni textura. Sin horizonte visible.
A6: Encuadre | B6: Producto de frente, centrado, ocupando ~80 % del cuadro (10 % de margen en cada lado). Cámara a la altura del producto, sin inclinación.
A7: Luz | B7: Difusa y pareja (luz de ventana o dos luces suaves). Sin flash directo, sin sombras duras ni reflejos que tapen el texto.
A8: Formato y peso | B8: WebP, o JPG/PNG (nosotros convertimos). Calidad 80-85, ≤ 250 KB por foto. Espacio de color sRGB.
A9: Nombre del archivo | B9: odoo-<id>.webp (ejemplo: odoo-3829.webp). Segunda foto: odoo-3829-2.webp. Tomar el id de la columna «Odoo ID» de la hoja 1.
A10: Retoque | B10: Solo ajuste de brillo y recorte. Sin retoque con IA ni limpieza que altere rótulos, marcas o texto del empaque.
A11: Empaque | B11: El texto del empaque (marca, presentación, capas) debe poder leerse al 100 %. Si el empaque lleva la marca de un cliente, ver la columna «¿Marca de un cliente en el empaque?».
A12: FOTO DEL SITIO
A13: Medida | B13: Horizontal, mínimo 2400 px de ancho: 16:9 = 2400 × 1350; 4:3 = 2400 × 1800; 3:2 = 2400 × 1600; 16:10 = 3000 × 1875.
A14: Formato | B14: Original de la cámara o JPG calidad 90. No enviar capturas de WhatsApp ni imágenes comprimidas (WhatsApp baja la calidad). Mejor por correo, Drive o USB.
A15: Celular | B15: Cámara principal (no frontal), modo foto normal, sin modo retrato ni filtros, sin zoom digital, en horizontal.
A16: Retoque | B16: Ninguno. Sin IA, sin filtros.
A17: Personas | B17: Si salen personas reconocibles, autorización escrita de cada una.
A18: LOGOS
A19: Formato | B19: SVG, AI o PDF vectorial. Si no existe, PNG transparente de al menos 2000 px de ancho.
A20: ENTREGA
A21: Cómo | B21: Una carpeta por hoja (productos, sitio, logos). Nombre de archivo según cada hoja. Avisar con la lista de ids entregados.
A22: Después | B22: Claude convierte, optimiza, ejecuta content:curate, verifica y despliega. Cada foto nueva de producto libera su ficha para indexación.

Sheet 1 Fotos de producto
A1: 1. Fotos de producto que faltan (135 referencias)
A2: Una foto principal por fila. Se guarda como public/images/products/odoo-<id>.webp (2.ª foto: odoo-<id>-2.webp). Las filas sombreadas (prioridad 1) son las 55 fichas que hoy llevan noindex: con foto pasan a indexarse. Las medidas son recomendación nuestra para que todas se vean iguales en el catálogo.
A4: Prioridad | B4: Odoo ID | C4: SKU | D4: Categoría | E4: Subcategoría | F4: Producto | G4: Presentación | H4: Nombre de archivo | I4: Foto principal: qué mostrar | J4: Foto 2 (opcional) | K4: Medidas y formato | L4: ¿Marca de un cliente en el empaque? | M4: Estado | N4: Fecha de entrega | O4: Notas
A5: 1 - Alta (hoy noindex) | B5: 3668 | C5: 0126-HIG-07 | D5: Papel higiénico | E5: Higiénico | F5: Higiénico 12/1, XL, Mopc | G5: 12/1 | H5: odoo-3668.webp | I5: Paquete o fardo cerrado, de frente, con el empaque real y el texto legible (presentación 12/1, capas, marca). Al lado, 1 rollo fuera del empaque para ver diámetro y capas. | J5: Opcional: vista de lado o trasera con la información de la etiqueta (presentación, código de barras) legible. | K5: 1200 × 1200 px (1:1), mínimo 900 × 900. Fondo blanco puro. Producto ocupa ~80 % del cuadro. WebP o JPG, ≤ 250 KB. | L5: No detectada | M5: Pendiente
A6: 1 - Alta (hoy noindex) | B6: 4305 | C6: 0270-HIG-20 | D6: Papel higiénico | F6: Higiénico 48/1 Sin Envoltura S.D | G6: 48/1 | H6: odoo-4305.webp | I6: Paquete o fardo cerrado, de frente, con el empaque real y el texto legible (presentación 48/1, capas, marca). Al lado, 1 rollo fuera del empaque para ver diámetro y capas. | J6: Opcional: vista de lado o trasera con la información de la etiqueta (presentación, código de barras) legible. | K6: 1200 × 1200 px (1:1), mínimo 900 × 900. Fondo blanco puro. Producto ocupa ~80 % del cuadro. WebP o JPG, ≤ 250 KB. | L6: No detectada | M6: Pendiente
A7: 1 - Alta (hoy noindex) | B7: 3678 | C7: 0136-HIG-17 | D7: Papel higiénico | E7: Higiénico | F7: Higiénico 48/1, M, Individual Ocean Breeze | G7: 48/1 | H7: odoo-3678.webp | I7: Paquete o fardo cerrado, de frente, con el empaque real y el texto legible (presentación 48/1, capas, marca). Al lado, 1 rollo fuera del empaque para ver diámetro y capas. | J7: Opcional: vista de lado o trasera con la información de la etiqueta (presentación, código de barras) legible. | K7: 1200 × 1200 px (1:1), mínimo 900 × 900. Fondo blanco puro. Producto ocupa ~80 % del cuadro. WebP o JPG, ≤ 250 KB. | L7: No detectada | M7: Pendiente
A8: 1 - Alta (hoy noindex) | B8: 4237 | C8: 0333-HIG-17 | D8: Papel higiénico | E8: Higiénico | F8: Higiénico 48/1, sin envoltura 5 pulgoso, 105 gr | G8: 48/1 | H8: odoo-4237.webp | I8: Paquete o fardo cerrado, de frente, con el empaque real y el texto legible (presentación 48/1, capas, marca). Al lado, 1 rollo fuera del empaque para ver diámetro y capas. | J8: Opcional: vista de lado o trasera con la información de la etiqueta (presentación, código de barras) legible. | K8: 1200 × 1200 px (1:1), mínimo 900 × 900. Fondo blanco puro. Producto ocupa ~80 % del cuadro. WebP o JPG, ≤ 250 KB. | L8: No detectada | M8: Pendiente
A9: 1 - Alta (hoy noindex) | B9: 3549 | C9: 0007-HIG-03 | D9: Papel higiénico | E9: Jumbo | F9: Higiénico Jumbo 12/1, Especial | G9: 12/1 | H9: odoo-3549.webp | I9: Rollo jumbo (bobina grande) de frente y de perfil, con la cinta o etiqueta legible; incluir el empaque si lo tiene. | J9: Opcional: vista de lado o trasera con la información de la etiqueta (presentación, código de barras) legible. | K9: 1200 × 1200 px (1:1), mínimo 900 × 900. Fondo blanco puro. Producto ocupa ~80 % del cuadro. WebP o JPG, ≤ 250 KB. | L9: No detectada | M9: Pendiente
A10: 1 - Alta (hoy noindex) | B10: 4012 | C10: 0460-PAP-27 | D10: Papel higiénico | F10: Papel Higiénico 12/1 Bionatural | G10: 12/1 | H10: odoo-4012.webp | I10: Paquete o fardo cerrado, de frente, con el empaque real y el texto legible (presentación 12/1, capas, marca). Al lado, 1 rollo fuera del empaque para ver diámetro y capas. | J10: Opcional: vista de lado o trasera con la información de la etiqueta (presentación, código de barras) legible. | K10: 1200 × 1200 px (1:1), mínimo 900 × 900. Fondo blanco puro. Producto ocupa ~80 % del cuadro. WebP o JPG, ≤ 250 KB. | L10: No detectada | M10: Pendiente
A11: 1 - Alta (hoy noindex) | B11: 3861 | C11: 0316-PAP-09 | D11: Papel higiénico | F11: Papel Higiénico 12/1 M Ocean Breeze | G11: 12/1 | H11: odoo-3861.webp | I11: Paquete o fardo cerrado, de frente, con el empaque real y el texto legible (presentación 12/1, capas, marca). Al lado, 1 rollo fuera del empaque para ver diámetro y capas. | J11: Opcional: vista de lado o trasera con la información de la etiqueta (presentación, código de barras) legible. | K11: 1200 × 1200 px (1:1), mínimo 900 × 900. Fondo blanco puro. Producto ocupa ~80 % del cuadro. WebP o JPG, ≤ 250 KB. | L11: No detectada | M11: Pendiente
A12: 1 - Alta (hoy noindex) | B12: 3866 | C12: 0321-PAP-11 | D12: Papel higiénico | F12: Papel Higiénico 48/1 M Individual Ocean Breeze | G12: 48/1 | H12: odoo-3866.webp | I12: Paquete o fardo cerrado, de frente, con el empaque real y el texto legible (presentación 48/1, capas, marca). Al lado, 1 rollo fuera del empaque para ver diámetro y capas. | J12: Opcional: vista de lado o trasera con la información de la etiqueta (presentación, código de barras) legible. | K12: 1200 × 1200 px (1:1), mínimo 900 × 900. Fondo blanco puro. Producto ocupa ~80 % del cuadro. WebP o JPG, ≤ 250 KB. | L12: No detectada | M12: Pendiente
A13: 1 - Alta (hoy noindex) | B13: 3942 | C13: 0397-PAP-24 | D13: Papel higiénico | F13: Papel Higiénico 6/1 9 Lbs | G13: 6/1 | H13: odoo-3942.webp | I13: Paquete o fardo cerrado, de frente, con el empaque real y el texto legible (presentación 6/1, capas, marca). Al lado, 1 rollo fuera del empaque para ver diámetro y capas. | J13: Opcional: vista de lado o trasera con la información de la etiqueta (presentación, código de barras) legible. | K13: 1200 × 1200 px (1:1), mínimo 900 × 900. Fondo blanco puro. Producto ocupa ~80 % del cuadro. WebP o JPG, ≤ 250 KB. | L13: No detectada | M13: Pendiente
A14: 1 - Alta (hoy noindex) | B14: 3938 | C14: 0393-PAP-23 | D14: Papel higiénico | F14: Papel Higiénico Jumbo 16 Libras 12/1 Caja | G14: 12/1 | H14: odoo-3938.webp | I14: Rollo jumbo (bobina grande) de frente y de perfil, con la cinta o etiqueta legible; incluir el empaque si lo tiene. | J14: Opcional: vista de lado o trasera con la información de la etiqueta (presentación, código de barras) legible. | K14: 1200 × 1200 px (1:1), mínimo 900 × 900. Fondo blanco puro. Producto ocupa ~80 % del cuadro. WebP o JPG, ≤ 250 KB. | L14: No detectada | M14: Pendiente
A15: 1 - Alta (hoy noindex) | B15: 3708 | C15: 0166-PAP-02 | D15: Papel higiénico | E15: Higiénico | F15: Papel Higiénico Xtra 30/1 | G15: 30/1 | H15: odoo-3708.webp | I15: Paquete o fardo cerrado, de frente, con el empaque real y el texto legible (presentación 30/1, capas, marca). Al lado, 1 rollo fuera del empaque para ver diámetro y capas. | J15: Opcional: vista de lado o trasera con la información de la etiqueta (presentación, código de barras) legible. | K15: 1200 × 1200 px (1:1), mínimo 900 × 900. Fondo blanco puro. Producto ocupa ~80 % del cuadro. WebP o JPG, ≤ 250 KB. | L15: SÍ: el nombre original traía una marca de cliente; fotografiar sin la marca visible o con su autorización | M15: Pendiente
A16: 1 - Alta (hoy noindex) | B16: 4214 | C16: 0889-TOA-33 | D16: Toallas de papel | F16: Toalla Cocina 2/1 Precortada Cja 9/2 (18) | G16: 2/1 | H16: odoo-4214.webp | I16: Paquete o caja cerrada de frente con el empaque real legible (presentación 2/1). Al lado, 1 rollo de toalla fuera del empaque. | J16: Opcional: vista de lado o trasera con la información de la etiqueta (presentación, código de barras) legible. | K16: 1200 × 1200 px (1:1), mínimo 900 × 900. Fondo blanco puro. Producto ocupa ~80 % del cuadro. WebP o JPG, ≤ 250 KB. | L16: No detectada | M16: Pendiente
A17: 1 - Alta (hoy noindex) | B17: 3796 | C17: 0251-TOA-28 | D17: Toallas de papel | F17: Toalla Económica 6/1 | G17: 6/1 | H17: odoo-3796.webp | I17: Paquete o caja cerrada de frente con el empaque real legible (presentación 6/1). Al lado, 1 rollo de toalla fuera del empaque. | J17: Opcional: vista de lado o trasera con la información de la etiqueta (presentación, código de barras) legible. | K17: 1200 × 1200 px (1:1), mínimo 900 × 900. Fondo blanco puro. Producto ocupa ~80 % del cuadro. WebP o JPG, ≤ 250 KB. | L17: No detectada | M17: Pendiente
A18: 1 - Alta (hoy noindex) | B18: 4266 | C18: 0265-TOA-36 | D18: Toallas de papel | F18: Toalla Económica Xtra 6/1 | G18: 6/1 | H18: odoo-4266.webp | I18: Paquete o caja cerrada de frente con el empaque real legible (presentación 6/1). Al lado, 1 rollo de toalla fuera del empaque. | J18: Opcional: vista de lado o trasera con la información de la etiqueta (presentación, código de barras) legible. | K18: 1200 × 1200 px (1:1), mínimo 900 × 900. Fondo blanco puro. Producto ocupa ~80 % del cuadro. WebP o JPG, ≤ 250 KB. | L18: No detectada | M18: Pendiente
A19: 1 - Alta (hoy noindex) | B19: 4094 | C19: 0889-TOA-33 | D19: Toallas de papel | F19: Toalla Especial 6/1 830 Grs | G19: 6/1 | H19: odoo-4094.webp | I19: Paquete o caja cerrada de frente con el empaque real legible (presentación 6/1). Al lado, 1 rollo de toalla fuera del empaque. | J19: Opcional: vista de lado o trasera con la información de la etiqueta (presentación, código de barras) legible. | K19: 1200 × 1200 px (1:1), mínimo 900 × 900. Fondo blanco puro. Producto ocupa ~80 % del cuadro. WebP o JPG, ≤ 250 KB. | L19: No detectada | M19: Pendiente
A20: 1 - Alta (hoy noindex) | B20: 3770 | C20: 0228-TOA-17 | D20: Toallas de papel | E20: Toalla | F20: Toalla TAD 13 Libras 6/1 con | G20: 6/1 | H20: odoo-3770.webp | I20: Paquete o caja cerrada de frente con el empaque real legible (presentación 6/1). Al lado, 1 rollo de toalla fuera del empaque. | J20: Opcional: vista de lado o trasera con la información de la etiqueta (presentación, código de barras) legible. | K20: 1200 × 1200 px (1:1), mínimo 900 × 900. Fondo blanco puro. Producto ocupa ~80 % del cuadro. WebP o JPG, ≤ 250 KB. | L20: No detectada | M20: Pendiente
A21: 1 - Alta (hoy noindex) | B21: 3771 | C21: 0229-TOA-18 | D21: Toallas de papel | E21: Toalla | F21: Toalla TAD 6/1 Pro | G21: 6/1 | H21: odoo-3771.webp | I21: Paquete o caja cerrada de frente con el empaque real legible (presentación 6/1). Al lado, 1 rollo de toalla fuera del empaque. | J21: Opcional: vista de lado o trasera con la información de la etiqueta (presentación, código de barras) legible. | K21: 1200 × 1200 px (1:1), mínimo 900 × 900. Fondo blanco puro. Producto ocupa ~80 % del cuadro. WebP o JPG, ≤ 250 KB. | L21: No detectada | M21: Pendiente
A22: 1 - Alta (hoy noindex) | B22: 4219 | C22: 0889-TOA-34 | D22: Toallas de papel | F22: Toalla TAD Caja 12/1 | G22: 12/1 | H22: odoo-4219.webp | I22: Paquete o caja cerrada de frente con el empaque real legible (presentación 12/1). Al lado, 1 rollo de toalla fuera del empaque. | J22: Opcional: vista de lado o trasera con la información de la etiqueta (presentación, código de barras) legible. | K22: 1200 × 1200 px (1:1), mínimo 900 × 900. Fondo blanco puro. Producto ocupa ~80 % del cuadro. WebP o JPG, ≤ 250 KB. | L22: No detectada | M22: Pendiente
A23: 1 - Alta (hoy noindex) | B23: 3901 | C23: 0356-TOA-38 | D23: Toallas de papel | F23: Toalla TAD Económica 6/1 | G23: 6/1 | H23: odoo-3901.webp | I23: Paquete o caja cerrada de frente con el empaque real legible (presentación 6/1). Al lado, 1 rollo de toalla fuera del empaque. | J23: Opcional: vista de lado o trasera con la información de la etiqueta (presentación, código de barras) legible. | K23: 1200 × 1200 px (1:1), mínimo 900 × 900. Fondo blanco puro. Producto ocupa ~80 % del cuadro. WebP o JPG, ≤ 250 KB. | L23: No detectada | M23: Pendiente
A24: 1 - Alta (hoy noindex) | B24: 3773 | C24: 0231-TOA-20 | D24: Toallas de papel | E24: Toalla | F24: Toalla TAD Smc 6/1 | G24: 6/1 | H24: odoo-3773.webp | I24: Paquete o caja cerrada de frente con el empaque real legible (presentación 6/1). Al lado, 1 rollo de toalla fuera del empaque. | J24: Opcional: vista de lado o trasera con la información de la etiqueta (presentación, código de barras) legible. | K24: 1200 × 1200 px (1:1), mínimo 900 × 900. Fondo blanco puro. Producto ocupa ~80 % del cuadro. WebP o JPG, ≤ 250 KB. | L24: No detectada | M24: Pendiente
A25: 1 - Alta (hoy noindex) | B25: 4158 | C25: 0889-TOA-34 | D25: Toallas de papel | F25: Toallacocina Individual Precortada | H25: odoo-4158.webp | I25: Paquete o caja cerrada de frente con el empaque real legible (la presentación que figure en el empaque). Al lado, 1 rollo de toalla fuera del empaque. | J25: Opcional: vista de lado o trasera con la información de la etiqueta (presentación, código de barras) legible. | K25: 1200 × 1200 px (1:1), mínimo 900 × 900. Fondo blanco puro. Producto ocupa ~80 % del cuadro. WebP o JPG, ≤ 250 KB. | L25: No detectada | M25: Pendiente
A26: 1 - Alta (hoy noindex) | B26: 3774 | C26: 0232-TOA-21 | D26: Toallas de papel | E26: Toalla | F26: Toallas 6/1 2/1 Ocean Breeze | G26: 6/1 | H26: odoo-3774.webp | I26: Paquete o caja cerrada de frente con el empaque real legible (presentación 6/1). Al lado, 1 rollo de toalla fuera del empaque. | J26: Opcional: vista de lado o trasera con la información de la etiqueta (presentación, código de barras) legible. | K26: 1200 × 1200 px (1:1), mínimo 900 × 900. Fondo blanco puro. Producto ocupa ~80 % del cuadro. WebP o JPG, ≤ 250 KB. | L26: No detectada | M26: Pendiente
A27: 1 - Alta (hoy noindex) | B27: 3777 | C27: 0235-TOA-24 | D27: Toallas de papel | E27: Toalla | F27: Toallas Cocina 12/3 Ocean Breeze | G27: 12/3 | H27: odoo-3777.webp | I27: Paquete o caja cerrada de frente con el empaque real legible (presentación 12/3). Al lado, 1 rollo de toalla fuera del empaque. | J27: Opcional: vista de lado o trasera con la información de la etiqueta (presentación, código de barras) legible. | K27: 1200 × 1200 px (1:1), mínimo 900 × 900. Fondo blanco puro. Producto ocupa ~80 % del cuadro. WebP o JPG, ≤ 250 KB. | L27: No detectada | M27: Pendiente
A28: 1 - Alta (hoy noindex) | B28: 3778 | C28: 0236-TOA-25 | D28: Toallas de papel | E28: Toalla | F28: Toallas Eco 6/1 Xtra | G28: 6/1 | H28: odoo-3778.webp | I28: Paquete o caja cerrada de frente con el empaque real legible (presentación 6/1). Al lado, 1 rollo de toalla fuera del empaque. | J28: Opcional: vista de lado o trasera con la información de la etiqueta (presentación, código de barras) legible. | K28: 1200 × 1200 px (1:1), mínimo 900 × 900. Fondo blanco puro. Producto ocupa ~80 % del cuadro. WebP o JPG, ≤ 250 KB. | L28: No detectada | M28: Pendiente
A29: 1 - Alta (hoy noindex) | B29: 4277 | C29: 0269-DIN-01 | D29: Servilletas | F29: Dinner 12/100 doblez 1/4 | G29: 12/100 | H29: odoo-4277.webp | I29: Paquete cerrado de frente con el empaque real legible (presentación 12/100). Al lado, 1 servilleta doblada como se usa. | J29: Opcional: vista de lado o trasera con la información de la etiqueta (presentación, código de barras) legible. | K29: 1200 × 1200 px (1:1), mínimo 900 × 900. Fondo blanco puro. Producto ocupa ~80 % del cuadro. WebP o JPG, ≤ 250 KB. | L29: No detectada | M29: Pendiente
A30: 1 - Alta (hoy noindex) | B30: 4213 | C30: 0889-DIS-06 | D30: Servilletas | F30: Dispenser Comprimidas 25 de 185 fardo | H30: odoo-4213.webp | I30: Paquete de servilletas para dispensador, cerrado y de frente, con empaque legible (la presentación que figure en el empaque). Al lado, unas servilletas asomando. | J30: Opcional: vista de lado o trasera con la información de la etiqueta (presentación, código de barras) legible. | K30: 1200 × 1200 px (1:1), mínimo 900 × 900. Fondo blanco puro. Producto ocupa ~80 % del cuadro. WebP o JPG, ≤ 250 KB. | L30: No detectada | M30: Pendiente
A31: 1 - Alta (hoy noindex) | B31: 3726 | C31: 0184-SER-10 | D31: Servilletas | E31: Cocktail timbradas | F31: Servilleta Cocktail 1000/1 | G31: 1000/1 | H31: odoo-3726.webp | I31: Paquete cerrado de frente con el empaque real legible (presentación 1000/1). Al lado, 1 servilleta doblada como se usa. | J31: Opcional: vista de lado o trasera con la información de la etiqueta (presentación, código de barras) legible. | K31: 1200 × 1200 px (1:1), mínimo 900 × 900. Fondo blanco puro. Producto ocupa ~80 % del cuadro. WebP o JPG, ≤ 250 KB. | L31: SÍ: el nombre original traía una marca de cliente; fotografiar sin la marca visible o con su autorización | M31: Pendiente
A32: 1 - Alta (hoy noindex) | B32: 3732 | C32: 0190-SER-16 | D32: Servilletas | F32: Servilletas 60/1 | G32: 60/1 | H32: odoo-3732.webp | I32: Paquete cerrado de frente con el empaque real legible (presentación 60/1). Al lado, 1 servilleta doblada como se usa. | J32: Opcional: vista de lado o trasera con la información de la etiqueta (presentación, código de barras) legible. | K32: 1200 × 1200 px (1:1), mínimo 900 × 900. Fondo blanco puro. Producto ocupa ~80 % del cuadro. WebP o JPG, ≤ 250 KB. | L32: No detectada | M32: Pendiente
A33: 1 - Alta (hoy noindex) | B33: 3747 | C33: 0205-SER-31 | D33: Servilletas | E33: Dinner timbradas | F33: Servilletas Dinner | H33: odoo-3747.webp | I33: Paquete cerrado de frente con el empaque real legible (la presentación que figure en el empaque). Al lado, 1 servilleta doblada como se usa. | J33: Opcional: vista de lado o trasera con la información de la etiqueta (presentación, código de barras) legible. | K33: 1200 × 1200 px (1:1), mínimo 900 × 900. Fondo blanco puro. Producto ocupa ~80 % del cuadro. WebP o JPG, ≤ 250 KB. | L33: SÍ: el nombre original traía una marca de cliente; fotografiar sin la marca visible o con su autorización | M33: Pendiente
A34: 1 - Alta (hoy noindex) | B34: 4311 | C34: 0272-SER-54 | D34: Servilletas | F34: Servilletas Impresa | H34: odoo-4311.webp | I34: Paquete cerrado de frente con el empaque real legible (la presentación que figure en el empaque). Al lado, 1 servilleta doblada como se usa. | J34: Opcional: vista de lado o trasera con la información de la etiqueta (presentación, código de barras) legible. | K34: 1200 × 1200 px (1:1), mínimo 900 × 900. Fondo blanco puro. Producto ocupa ~80 % del cuadro. WebP o JPG, ≤ 250 KB. | L34: SÍ: el nombre original traía una marca de cliente; fotografiar sin la marca visible o con su autorización | M34: Pendiente
A35: 1 - Alta (hoy noindex) | B35: 3576 | C35: 0034-CAR-01 | D35: Jabón y limpieza | F35: Cartucho Jabón Espuma, Caja de 4 UD | H35: odoo-3576.webp | I35: Envase (botella, galón o bidón) cerrado, de frente, con la etiqueta completa y legible. | J35: Opcional: vista de lado o trasera con la información de la etiqueta (presentación, código de barras) legible. | K35: 1200 × 1200 px (1:1), mínimo 900 × 900. Fondo blanco puro. Producto ocupa ~80 % del cuadro. WebP o JPG, ≤ 250 KB. | L35: No detectada | M35: Pendiente
A36: 1 - Alta (hoy noindex) | B36: 3990 | C36: 0438-DES-01 | D36: Jabón y limpieza | F36: Desinfectante Lavanda Mibea 4/1 | G36: 4/1 | H36: odoo-3990.webp | I36: Envase (botella, galón o bidón) cerrado, de frente, con la etiqueta completa y legible. | J36: Opcional: vista de lado o trasera con la información de la etiqueta (presentación, código de barras) legible. | K36: 1200 × 1200 px (1:1), mínimo 900 × 900. Fondo blanco puro. Producto ocupa ~80 % del cuadro. WebP o JPG, ≤ 250 KB. | L36: No detectada | M36: Pendiente
A37: 1 - Alta (hoy noindex) | B37: 3992 | C37: 0440-DIS-04 | D37: Jabón y limpieza | F37: Dispensador Inox Jumbo | H37: odoo-3992.webp | I37: Envase (botella, galón o bidón) cerrado, de frente, con la etiqueta completa y legible. | J37: Opcional: vista de lado o trasera con la información de la etiqueta (presentación, código de barras) legible. | K37: 1200 × 1200 px (1:1), mínimo 900 × 900. Fondo blanco puro. Producto ocupa ~80 % del cuadro. WebP o JPG, ≤ 250 KB. | L37: No detectada | M37: Pendiente
A38: 1 - Alta (hoy noindex) | B38: 3603 | C38: 0061-DIS-01 | D38: Jabón y limpieza | F38: Dispensador de Jabón Cartucho | H38: odoo-3603.webp | I38: Envase (botella, galón o bidón) cerrado, de frente, con la etiqueta completa y legible. | J38: Opcional: vista de lado o trasera con la información de la etiqueta (presentación, código de barras) legible. | K38: 1200 × 1200 px (1:1), mínimo 900 × 900. Fondo blanco puro. Producto ocupa ~80 % del cuadro. WebP o JPG, ≤ 250 KB. | L38: No detectada | M38: Pendiente
A39: 1 - Alta (hoy noindex) | B39: 3604 | C39: 0062-DIS-02 | D39: Jabón y limpieza | F39: Dispensador de Jabón Líquido C/valvula | H39: odoo-3604.webp | I39: Envase (botella, galón o bidón) cerrado, de frente, con la etiqueta completa y legible. | J39: Opcional: vista de lado o trasera con la información de la etiqueta (presentación, código de barras) legible. | K39: 1200 × 1200 px (1:1), mínimo 900 × 900. Fondo blanco puro. Producto ocupa ~80 % del cuadro. WebP o JPG, ≤ 250 KB. | L39: No detectada | M39: Pendiente
A40: 1 - Alta (hoy noindex) | B40: 3991 | C40: 0439-DIS-03 | D40: Jabón y limpieza | F40: Dispensador de Papel Jumbo | H40: odoo-3991.webp | I40: Envase (botella, galón o bidón) cerrado, de frente, con la etiqueta completa y legible. | J40: Opcional: vista de lado o trasera con la información de la etiqueta (presentación, código de barras) legible. | K40: 1200 × 1200 px (1:1), mínimo 900 × 900. Fondo blanco puro. Producto ocupa ~80 % del cuadro. WebP o JPG, ≤ 250 KB. | L40: No detectada | M40: Pendiente
A41: 1 - Alta (hoy noindex) | B41: 4144 | C41: 0889-DIS-05 | D41: Jabón y limpieza | F41: Dispensador de Toalla | H41: odoo-4144.webp | I41: Envase (botella, galón o bidón) cerrado, de frente, con la etiqueta completa y legible. | J41: Opcional: vista de lado o trasera con la información de la etiqueta (presentación, código de barras) legible. | K41: 1200 × 1200 px (1:1), mínimo 900 × 900. Fondo blanco puro. Producto ocupa ~80 % del cuadro. WebP o JPG, ≤ 250 KB. | L41: No detectada | M41: Pendiente
...

Sheet 2 Fotos existentes
A1: 2. Fotos de producto que ya están en el sitio (33 referencias)
A2: Revisión automática por tamaño y proporción. No se juzga el contenido de la foto: si alguna tiene rótulos deformados o retoque que altere el empaque, conviene re-tomarla aunque aparezca OK.
A4: Odoo ID | B4: SKU | C4: Producto | D4: Archivo actual | E4: Tamaño actual (px) | F4: Observación | G4: Acción | H4: Estado | I4: Notas
A5: 3552 | B5: SER-01 | C5: Servilletas Dispenser Bonche 10 Paquetes | D5: odoo-3552.webp | E5: 1000 × 507 | F5: Proporción alargada (se recorta o queda con mucho espacio vacío) | G5: Re-tomar en 1200 × 1200 px, fondo blanco | H5: Pendiente
A6: 3555 | B6: 0013-TOA-02 | C6: Toalla Kraft 600 Pies 6/1 | D6: odoo-3555.webp | E6: 422 × 386 | F6: Baja resolución (lado mayor < 900 px) | G6: Re-tomar en 1200 × 1200 px, fondo blanco | H6: Pendiente
A7: 3695 | B7: 0153-JUM-09 | C7: Jumbo Económico 12/1, 2 Capas | D7: odoo-3695.webp | E7: 414 × 432 | F7: Baja resolución (lado mayor < 900 px) | G7: Re-tomar en 1200 × 1200 px, fondo blanco | H7: Pendiente
A8: 3710 | B8: 0168-PAÑ-01 | C8: Pañuelos Faciales 30/1 Cubo Ocean Breeze | D8: odoo-3710.webp | E8: 796 × 795 | F8: Baja resolución (lado mayor < 900 px) | G8: Re-tomar en 1200 × 1200 px, fondo blanco | H8: Pendiente
A9: 3711 | B9: 0169-PAÑ-02 | C9: Pañuelos Faciales 30/1 Plano Ocean Breeze | D9: odoo-3711.webp | E9: 699 × 432 | F9: Baja resolución (lado mayor < 900 px); Proporción alargada (se recorta o queda con mucho espacio vacío) | G9: Re-tomar en 1200 × 1200 px, fondo blanco | H9: Pendiente
A10: 3723 | B10: 0181-SER-07 | C10: Servilleta C-Fold 24/100 | D10: odoo-3723.webp | E10: 524 × 282 | F10: Baja resolución (lado mayor < 900 px); Proporción alargada (se recorta o queda con mucho espacio vacío) | G10: Re-tomar en 1200 × 1200 px, fondo blanco | H10: Pendiente
A11: 3724 | B11: 0182-SER-08 | C11: Servilleta C-Fold 24/100 Kraft | D11: odoo-3724.webp | E11: 1000 × 568 | F11: Proporción alargada (se recorta o queda con mucho espacio vacío) | G11: Re-tomar en 1200 × 1200 px, fondo blanco | H11: Pendiente
A12: 3733 | B12: 0191-SER-17 | C12: Servilletas Blanca Disp. 10/500 Ocean Breeze | D12: odoo-3733.webp | E12: 1000 × 553 | F12: Proporción alargada (se recorta o queda con mucho espacio vacío) | G12: Re-tomar en 1200 × 1200 px, fondo blanco | H12: Pendiente
A13: 3736 | B13: 0194-SER-20 | C13: Servilletas Cocktail 8/500 1 PLY Kraft | D13: odoo-3736.webp | E13: 1000 × 639 | F13: Proporción alargada (se recorta o queda con mucho espacio vacío) | G13: Re-tomar en 1200 × 1200 px, fondo blanco | H13: Pendiente
A14: 3737 | B14: 0195-SER-21 | C14: Servilletas Cocktail 8/500 1 PLY Ocean Breeze | D14: odoo-3737.webp | E14: 880 × 575 | F14: Baja resolución (lado mayor < 900 px); Proporción alargada (se recorta o queda con mucho espacio vacío) | G14: Re-tomar en 1200 × 1200 px, fondo blanco | H14: Pendiente
A15: 3739 | B15: 0197-SER-23 | C15: Servilletas Cuadrada 13X13-10/300 | D15: odoo-3739.webp | E15: 1000 × 741 | F15: Proporción alargada (se recorta o queda con mucho espacio vacío) | G15: Re-tomar en 1200 × 1200 px, fondo blanco | H15: Pendiente
A16: 3750 | B16: 0208-SER-34 | C16: Servilletas Kraft Disp.10/500 Ocean Breeze | D16: odoo-3750.webp | E16: 1000 × 663 | F16: Proporción alargada (se recorta o queda con mucho espacio vacío) | G16: Re-tomar en 1200 × 1200 px, fondo blanco | H16: Pendiente
... A37: 4180 | B37: 0889-SER-56 | C37: Servilletas Dispenser 10/400 | D37: odoo-4180.webp | E37: 1000 × 749 | F37: OK (conservar) | G37: Sin cambios | H37: No aplica

Sheet 3 Fotos del sitio
A1: 3. Fotos de la planta, marcas y el sitio
A2: Sin retoque con IA, con luz natural o de nave, horizontales. Entregar el archivo original de la cámara o JPG calidad 90 (nosotros lo convertimos a WebP). Si se toman con celular: modo foto normal, no «retrato», sin filtros ni HDR agresivo.
A4: # | B4: Toma | C4: Dónde se usa | D4: Orientación / proporción | E4: Tamaño recomendado | F4: Qué hay hoy | G4: Qué debe mostrar | H4: Qué evitar | I4: ¿Necesita autorización? | J4: Prioridad | K4: Estado | L4: Nombre de archivo que entregas | M4: Notas
A5: 1 | B5: Fachada y acceso | C5: Inicio (bloque «Planta»), Nosotros, cabecera de Nosotros | D5: Horizontal 16:9 | E5: 2400 × 1350 px | F5: Hoy: section-nosotros.webp 1280 × 720 | G5: Frente del edificio de AG Supply en Las Palomas, Santiago, con el rótulo y la entrada visibles; de día, cielo despejado, cámara a la altura de los ojos, sin autos tapando la entrada. | H5: Contraluz fuerte, cables en primer plano, personas identificables sin autorización. | I5: No | J5: Media | K5: Pendiente
A6: 2 | B6: Bobinas de materia prima | C6: Inicio (cabecera), Planta paso 1 «Bobinas y materia prima» | D6: Horizontal 16:9 | E6: 2400 × 1350 px | F6: Hoy: hero-2.webp 1280 × 720 (retocada con IA) | G6: Almacén de bobinas de papel base, con la bobina de mayor diámetro en primer plano y el resto en perspectiva. Luz de nave o natural. | H6: Rótulos de proveedores legibles; retoque con IA; montacargas ajenos a la planta. | I6: No | J6: Alta | K6: Pendiente
A7: 3 | B7: Rebobinadora en operación | C7: Planta paso 2, cabecera de la categoría Papel higiénico | D7: Horizontal 4:3 | E7: 2400 × 1800 px | F7: Hoy: planta-2.webp 1200 × 900 (retocada con IA) | G7: Rebobinadora con una bobina en proceso y, si es posible, un operario trabajando (de espaldas o con autorización). Enfoque en la bobina y el papel que sale. | H7: Equipo detenido y vacío; reflejos fuertes. | I7: Sí, si sale una persona | J7: Alta | K7: Pendiente
A8: 4 | B8: Corte y conversión | C8: Planta paso 3, cabecera de la categoría Toallas | D8: Horizontal 4:3 | E8: 2400 × 1800 px | F8: Hoy: planta-3.webp 1200 × 900 (retocada con IA) | G8: Máquina de corte o conversión en funcionamiento, con el papel pasando por la zona de corte. Plano medio de la máquina. | H8: Zonas de peligro sin protección a la vista; rótulos de terceros. | I8: Sí, si sale una persona | J8: Alta | K8: Pendiente
A9: 5 | B9: Doblado e interfoliado | C9: Planta paso 3 (alternativa) y categoría Servilletas / Interfoliados | D9: Horizontal 4:3 | E9: 2400 × 1800 px | F9: No existe hoy | G9: Máquina de doblado con las servilletas o toallas interfoliadas saliendo apiladas; detalle de las hojas dobladas. | H9: Producto de un cliente con marca visible sin autorización. | I9: No | J9: Media | K9: Pendiente
A10: 6 | B10: Línea de empaque | C10: Planta paso 4, cabecera de la categoría Servilletas | D10: Horizontal 4:3 | E10: 2400 × 1800 px | F10: Hoy: planta-4.webp 1200 × 900 (retocada con IA) | G10: Línea de empaque con el empaque real de Ocean Breeze y de Bonche legible, producto entrando en bolsa o caja. Debe poder leerse la marca sin deformaciones. | H10: Rótulos deformados; empaques de marca de clientes. | I10: Sí, si sale una persona | J10: Alta | K10: Pendiente
A11: 7 | B11: Almacén de producto terminado y despacho | C11: Planta paso 5, cabecera del Catálogo | D11: Horizontal 4:3 | E11: 2400 × 1800 px | F11: Hoy: planta-5.webp 1200 × 900 (retocada con IA) | G11: Paletas o cajas de producto terminado ordenadas, con el camión de AG Supply al fondo si existe. Pasillo despejado, buena luz. | H11: Cajas con marca de cliente legible; montacargas ajenos. | I11: No | J11: Media | K11: Pendiente
A12: 8 | B12: Línea Ocean Breeze (producto) | C12: Página Ocean Breeze, Inicio (marcas) | D12: Horizontal 16:10 | E12: 3000 × 1875 px | F12: No existe hoy | G12: Todos los productos Ocean Breeze juntos (papel higiénico, toalla, servilleta, etc.) de frente, sobre fondo blanco liso o gris muy claro, con el logo legible. Luz difusa, sin sombras duras. | H12: Fondo con textura o color; productos de otras marcas. | I12: No | J12: Alta | K12: Pendiente
A13: 9 | B13: Línea Bonche (producto) | C13: Página Bonche, Inicio (marcas) | D13: Horizontal 16:10 | E13: 3000 × 1875 px | F13: Hoy: brand-bonche-hero.webp 1600 × 1000 sobre fondo verde; bonche-productos.webp 1379 × 399 recorte hecho por nosotros | G13: Todos los productos Bonche juntos de frente, sobre fondo blanco liso, con el logo legible. Con fondo blanco el recorte es limpio. Si es posible, entregar también el PNG recortado con fondo transparente. | H13: Fondo verde (obliga a recortar y deja halos); retoque con IA. | I13: No | J13: Alta | K13: Pendiente
A14: 10 | B14: Producto en uso en un cliente | C14: Inicio (mercados), Nosotros | D14: Horizontal 3:2 | E14: 2400 × 1600 px | F14: No existe hoy | G14: Producto AG Supply en un hotel, restaurante o comercio cliente (dispensador, mesa servida, baño). Que se vea el producto y su empaque o dispensador sin identificar a clientes finales. | H14: Marcas o rostros de terceros visibles. | I14: Sí: del cliente y de las personas que salgan | J14: Baja | K14: Pendiente
A15: 11 | B15: Fotos para redes y compartir | C15: Imagen al compartir el enlace (Open Graph) en WhatsApp, Facebook, LinkedIn | D15: Horizontal 1.91:1 | E15: 1200 × 630 px | F15: Hoy: og.png 1200 × 630 generada por nosotros con el logo | G15: Opcional: si hay una foto de la planta o del producto que represente mejor a la empresa, usarla de fondo con el logo encima. | H15: Texto pequeño (no se lee en miniatura). | I15: No | J15: Baja | K15: Pendiente

Sheet 4 Logos y marca
A1: 4. Logos, iconos y marca
A2: Todo en formato vectorial cuando sea posible. Sin vector, mínimo PNG con fondo transparente a 2000 px de ancho.
A4: # | B4: Entregable | C4: Formato y tamaño | D4: Detalles | E4: Qué hay hoy | F4: Dónde se usa | G4: Prioridad | H4: Estado | I4: Archivo entregado | J4: Notas
A5: 1 | B5: Logotipo AG Supply, color, vector | C5: SVG, AI o PDF vectorial (preferible SVG) | D5: Fondo transparente. Con espacio de respeto alrededor. | E5: Hoy: PNG 1080 × 328 y WebP 540 × 164 recortados del sitio anterior. En tamaños grandes se ve borroso. | F5: Cabecera, pie, OG, correo, impresos | G5: Alta | H5: Pendiente
A6: 2 | B6: Logotipo AG Supply, versión blanca | C6: SVG o PNG transparente ≥ 2000 px de ancho | D6: Todo en blanco, para fondos azules. | E6: No existe. Solo se necesita si se quiere usar el logo sobre la banda azul. | F6: Bandas azules, redes | G6: Baja | H6: Pendiente
A7: 3 | B7: Monograma «AG» (icono) | C7: SVG + PNG 512 × 512 px, transparente, cuadrado | D7: Proporción 1:1 con margen del 10 %. | E7: Hoy: icon.png 128 × 128 (paleta de 256 colores) y monograma 500 × 500 con fondo. | F7: Pestaña del navegador (favicon), icono en el móvil, perfil de redes | G7: Media | H7: Pendiente
A8: 4 | B8: Logotipo Ocean Breeze, vector | C8: SVG, AI o PDF | D8: Fondo transparente. | E8: Hoy: WebP 800 × 500. | F8: Página de la marca, catálogo, Inicio | G8: Media | H8: Pendiente
A9: 5 | B9: Logotipo Bonche, vector | C9: SVG, AI o PDF | D9: Fondo transparente. Versión con y sin celeste/naranja si existe. | E9: Hoy: WebP 800 × 500. | F9: Página de la marca, catálogo, Inicio | G9: Media | H9: Pendiente
A10: 6 | B10: Códigos de color oficiales | C10: HEX, Pantone o CMYK de AG Supply, Ocean Breeze y Bonche | D10: Una tabla en Word o Excel, o el manual de marca. | E10: Usamos #1C75BC (azul) y #ED1C24 (rojo) tomados del logo; no hay manual oficial. | F10: Confirmar que el sitio usa los colores correctos | G10: Media | H10: Pendiente
A11: 7 | B11: Tipografía oficial del logo | C11: Nombre de la fuente y licencia (si existe) | D11: Solo si la marca tiene una definida. | E11: El sitio usa Archivo (titulares) e IBM Plex Sans (texto), elegidas por parecido con el logo. | F11: Sitio y materiales | G11: Baja | H11: Pendiente
A12: 8 | B12: Manual de marca (si existe) | C12: PDF | D12: Usos permitidos, tamaños mínimos, colores. | E12: No se ha recibido. | F12: Consistencia en todos los canales | G12: Baja | H12: Pendiente

Sheet 5 Datos del cliente
A1: 5. Información que solo el cliente puede dar
A2: Nada de esto se publica como hecho hasta que se confirme. Escribe la respuesta en la columna «Respuesta del cliente».
A4: # | B4: Tema | C4: Qué necesitamos exactamente | D4: Dónde se usa | E4: Prioridad | F4: Estado | G4: Respuesta del cliente | H4: Fecha
A5: 1 | B5: Dirección completa | C5: Calle, número, sector, ciudad, provincia y código postal de la planta. Hoy solo dice «Sector Las Palomas, Santiago». | D5: Contacto, JSON-LD, Perfil de Empresa de Google | E5: Alta | F5: Pendiente
A6: 2 | B6: Horario definitivo | C6: Días y horas (¿sábado?, ¿festivos?). Hoy: lunes a viernes, 8:00 a. m. a 5:00 p. m. | D6: Todo el sitio, Perfil de Empresa de Google | E6: Alta | F6: Pendiente
A7: 3 | B7: Correo definitivo | C7: ¿Se mantiene agsupplycxc@gmail.com o hay un correo del dominio (@agsupply.com.do)? | D7: Contacto, formulario, pie de página | E7: Alta | F7: Pendiente
A8: 4 | B8: WhatsApp | C8: Confirmar que 809-612-2020 recibe WhatsApp y quién lo atiende en el horario publicado. | D8: Cotización, todos los botones de WhatsApp | E8: Alta | F8: Pendiente
A9: 5 | B9: Redes sociales | C9: Enlaces oficiales de Instagram (hoy @agsupplyrd), Facebook, LinkedIn y otras. | D9: Pie de página, datos estructurados | E9: Media | F9: Pendiente
A10: 6 | B10: Aprobación del diseño | C10: Revisar la versión publicada y decir qué se queda, qué cambia (colores, tipografía, secciones, textos). | D10: Todo el sitio | E10: Alta | F10: Pendiente
A11: 7 | B11: Revisión del inglés | C11: Revisar la versión /en/: términos técnicos, nombres de producto traducidos y el eslogan en inglés («Feel the clean», el oficial es «Siente la limpieza»). | D11: /en/ completo | E11: Alta | F11: Pendiente
A12: 8 | B12: Categorías que fabrica | C12: Confirmar que AG Supply fabrica papel higiénico, toallas, servilletas, interfoliados y facial, y que jabón, desechables y cubertería son suministrados. Indicar excepciones. | D12: Fichas («Fabricado» o «Suministrado»), FAQ, llms.txt | E12: Alta | F12: Pendiente
A13: 9 | B13: Toalla de tela | C13: «Toalla Tela Cocina» está marcada como no fabricada. Confirmar. | D13: Ficha de producto | E13: Baja | F13: Pendiente
A14: 10 | B14: Marcas de terceros | C14: Confirmar si Durasol y Mibea se muestran. Las demás (Chito, Pannez, Rancho, Samey, Senator, Jerez, Maine, Sumeh, Barcelo, Geto, La Terminal) se ocultaron del texto público. | D14: Catálogo | E14: Media | F14: Pendiente
A15: 11 | B15: Siglas internas | C15: Definir qué significan MW, HW, SD, U.R, TAD, SMC, XL, Lc, Mopc, SHH, MB (o dar un nombre público equivalente). | D15: Nombres de producto, búsqueda, FAQ | E15: Media | F15: Pendiente
A16: 12 | B16: Notación de presentación | C16: Qué significan 12/1, 48/1, 20/150: cantidad por paquete y por caja, y la unidad mínima de pedido. | D16: FAQ, cotización, fichas | E16: Media | F16: Pendiente
... A24: 20 | B24: Equipo y fotos de personas | C24: Si se quiere mostrar al equipo: nombres, cargos y autorización escrita de cada persona. | D24: Nosotros | E24: Baja | F24: Pendiente

Sheet 6 Odoo (catálogo)
A1: 6. Correcciones del catálogo en Odoo
A2: El sitio muestra el SKU tal como viene de Odoo: no se inventan ni reasignan códigos. Después de corregir en Odoo, se vuelve a importar el catálogo.
A4: Tipo | B4: SKU actual | C4: Producto | D4: Odoo ID | E4: Qué corregir | F4: Estado | G4: Notas
A5: SKU duplicado | B5: 0889-TOA-33 | C5: Toalla Bleach 750 Pies Caja 12/1 | D5: 4058 | E5: Asignar un SKU único a cada producto (hoy comparten código con otros). | F5: Pendiente
A6: SKU duplicado | B6: 0889-TOA-33 | C6: Toalla Cocina 2/1 Precortada Cja 9/2 (18) | D6: 4214 | E6: Asignar un SKU único a cada producto (hoy comparten código con otros). | F6: Pendiente
A7: SKU duplicado | B7: 0889-TOA-33 | C7: Toalla Especial 6/1 830 Grs | D7: 4094 | E7: Asignar un SKU único a cada producto (hoy comparten código con otros). | F7: Pendiente
A8: SKU duplicado | B8: 0889-TOA-33 | C8: Toalla Kraft 22 Lbs 6/1 1578 | D8: 4138 | E8: Asignar un SKU único a cada producto (hoy comparten código con otros). | F8: Pendiente
A9: SKU duplicado | B9: 0889-TOA-34 | C9: Toalla TAD Caja 12/1 | D9: 4219 | E9: Asignar un SKU único a cada producto (hoy comparten código con otros). | F9: Pendiente
A10: SKU duplicado | B10: 0889-TOA-34 | C10: Toallacocina Individual Precortada | D10: 4158 | E10: Asignar un SKU único a cada producto (hoy comparten código con otros). | F10: Pendiente
A11: SKU con formato inválido | B11: 0889-[08-02 | C11: Papel Higiénico 60 Mts Individual Ocean Breeze | D11: 4125 | E11: Corregir al formato NNNN-AAA-NN (por ejemplo 0889-TOA-33). El sitio oculta SKU inválidos. | F11: Pendiente
A12: SKU con formato inválido | B12: SER-01 | C12: Servilletas Dispenser Bonche 10 Paquetes | D12: 3552 | E12: Corregir al formato NNNN-AAA-NN (por ejemplo 0889-TOA-33). El sitio oculta SKU inválidos. | F12: Pendiente
A13: Producto sin SKU | C13: Cucharas Blanca MW 40/25 | D13: 4107 | E13: Asignar SKU en Odoo. | F13: Pendiente
A14: Producto sin SKU | C14: Tenedor MW Blanco 40/25 | D14: 4108 | E14: Asignar SKU en Odoo. | F14: Pendiente
A15: Producto sin SKU | C15: Funda 4 GLN 18X22 Blanca | D15: 3628 | E15: Asignar SKU en Odoo. | F15: Pendiente
A16: Producto sin SKU | C16: Plegadizas Papel Encerado Bonche (75 Pies X 12 Pulg) | D16: 4186 | E16: Asignar SKU en Odoo. | F16: Pendiente
A17: Posible errata | C17: Servilleta Dinner Azul 20150 2 PLY | E17: ¿Es 20/150? Confirmar y corregir el nombre. | F17: Pendiente
A18: Posible errata | C18: Toalla TAD 13 Libras 6/1 con | E18: Nombre truncado: completar. | F18: Pendiente
A19: Datos técnicos faltantes (opcional) | B19: 0284-COM-16 | C19: Combo Clear HW 2 PZAS Ten+cuchi | D19: 3829 | E19: Sin foto y sin datos técnicos (capas, medida, color, material…). Con foto o con datos la ficha deja de estar en noindex. | F19: Pendiente
A20: Datos técnicos faltantes (opcional) | B20: 0395-COM-17 | C20: Combo HW 1 Pieza Impreso 100/1 | D20: 3940 | E20: Sin foto y sin datos técnicos (capas, medida, color, material…). Con foto o con datos la ficha deja de estar en noindex. | F20: Pendiente
A21: Datos técnicos faltantes (opcional) | B21: 0001-COM-01 | C21: Combo HW 2 PZAS Impreso 100/1 | D21: 3543 | E21: Sin foto y sin datos técnicos (capas, medida, color, material…). Con foto o con datos la ficha deja de estar en noindex. | F21: Pendiente
A22: Datos técnicos faltantes (opcional) | B22: 0041-COM-03 | C22: Combo HW 2 PZAS Impreso 100/1. Hight. Bolsas Lisas | D22: 3583 | E22: Sin foto y sin datos técnicos (capas, medida, color, material…). Con foto o con datos la ficha deja de estar en noindex. | F22: Pendiente
A23: Datos técnicos faltantes (opcional) | B23: 0889-COM-12 | C23: Combos 2 Piezas Blancos MW 500/1 | D23: 4175 | E23: Sin foto y sin datos técnicos (capas, medida, color, material…). Con foto o con datos la ficha deja de estar en noindex. | F23: Pendiente
A24: Datos técnicos faltantes (opcional) | B24: 0046-COM-08 | C24: Combos en Caja HW 2 Piezas 500/1. Hight. Caja | D24: 3588 | E24: Sin foto y sin datos técnicos (capas, medida, color, material…). Con foto o con datos la ficha deja de estar en noindex. | F24: Pendiente
A25: Datos técnicos faltantes (opcional) | B25: 0274-COM-19 | C25: Combos en Caja HW 3 Piezas 10/25 Hight | D25: 4324 | E25: Sin foto y sin datos técnicos (capas, medida, color, material…). Con foto o con datos la ficha deja de estar en noindex. | F25: Pendiente
A26: Datos técnicos faltantes (opcional) | B26: 0285-CUC-06 | C26: Cuchillo Clear 1000/1 | D26: 3830 | E26: Sin foto y sin datos técnicos (capas, medida, color, material…). Con foto o con datos la ficha deja de estar en noindex. | F26: Pendiente
A27: Datos técnicos faltantes (opcional) | B27: 0286-TEN-04 | C27: Tenedor Clear 1000/1 | D27: 3831 | E27: Sin foto y sin datos técnicos (capas, medida, color, material…). Con foto o con datos la ficha deja de estar en noindex. | F27: Pendiente
A28: Datos técnicos faltantes (opcional) | B28: 0398-FAR-07 | C28: Fardo Funda Jardín | D28: 3943 | E28: Sin foto y sin datos técnicos (capas, medida, color, material…). Con foto o con datos la ficha deja de estar en noindex. | F28: Pendiente
A29: Datos técnicos faltantes (opcional) | B29: 0889-FUN-51 | C29: Funda MTZ 36 X 52 Hd Lisa 1/100 | D29: 4145 | E29: Sin foto y sin datos técnicos (capas, medida, color, material…). Con foto o con datos la ficha deja de estar en noindex. | F29: Pendiente
A30: Datos técnicos faltantes (opcional) | B30: 0377-PAP-19 | C30: Papel Encerado 16X24 Caja de 1000 | D30: 3922 | E30: Sin foto y sin datos técnicos (capas, medida, color, material…). Con foto o con datos la ficha deja de estar en noindex. | F30: Pendiente
... A33: Datos técnicos faltantes (opcional) | B33: 0256-PAP-15 | C33: Papel MG Impresión 12X11 1000/1 | D33: 4251 | E33: Sin foto y sin datos técnicos (capas, medida, color, material…). Con foto o con datos la ficha deja de estar en noindex. | F33: Pendiente
A34: Datos técnicos faltantes (opcional) | C34: Plegadizas Papel Encerado Bonche (75 Pies X 12 Pulg) | D34: 4186 | E34: Sin foto y sin datos técnicos (capas, medida, color, material…). Con foto o con datos la ficha deja de estar en noindex. | F34: Pendiente
A35: Datos técnicos faltantes (opcional) | B35: 0034-CAR-01 | C35: Cartucho Jabón Espuma, Caja de 4 UD | D35: 3576 | E35: Sin foto y sin datos técnicos (capas, medida, color, material…). Con foto o con datos la ficha deja de estar en noindex. | F35: Pendiente
A36: Datos técnicos faltantes (opcional) | B36: 0438-DES-01 | C36: Desinfectante Lavanda Mibea 4/1 | D36: 3990 | E36: Sin foto y sin datos técnicos (capas, medida, color, material…). Con foto o con datos la ficha deja de estar en noindex. | F36: Pendiente
A37: Datos técnicos faltantes (opcional) | B37: 0061-DIS-01 | C37: Dispensador de Jabón Cartucho | D37: 3603 | E37: Sin foto y sin datos técnicos (capas, medida, color, material…). Con foto o con datos la ficha deja de estar en noindex. | F37: Pendiente
A38: Datos técnicos faltantes (opcional) | B38: 0062-DIS-02 | C38: Dispensador de Jabón Líquido C/valvula | D38: 3604 | E38: Sin foto y sin datos técnicos (capas, medida, color, material…). Con foto o con datos la ficha deja de estar en noindex. | F38: Pendiente
A39: Datos técnicos faltantes (opcional) | B39: 0439-DIS-03 | C39: Dispensador de Papel Jumbo | D39: 3991 | E39: Sin foto y sin datos técnicos (capas, medida, color, material…). Con foto o con datos la ficha deja de estar en noindex. | F39: Pendiente
A40: Datos técnicos faltantes (opcional) | B40: 0889-DIS-05 | C40: Dispensador de Toalla | D40: 4144 | E40: Sin foto y sin datos técnicos (capas, medida, color, material…). Con foto o con datos la ficha deja de estar en noindex. | F40: Pendiente
A41: Datos técnicos faltantes (opcional) | B41: 0440-DIS-04 | C41: Dispensador Inox Jumbo | D41: 3992 | E41: Sin foto y sin datos técnicos (capas, medida, color, material…). Con foto o con datos la ficha deja de estar en noindex. | F41: Pendiente
A42: Datos técnicos faltantes (opcional) | B42: 0066-ESP-01 | C42: Esponja de Acero Inoxidable Durasol | D42: 3608 | E42: Sin foto y sin datos técnicos (capas, medida, color, material…). Con foto o con datos la ficha deja de estar en noindex. | F42: Pendiente
A43: Datos técnicos faltantes (opcional) | B43: 0067-ESP-02 | C43: Esponja Doble Uso Durasol | D43: 3609 | E43: Sin foto y sin datos técnicos (capas, medida, color, material…). Con foto o con datos la ficha deja de estar en noindex. | F43: Pendiente
...

Sheet 7 Técnico y Google
A1: 7. Tareas técnicas, de Google y de despliegue
A2: «Responsable» dice quién da el siguiente paso. Lo que dice Claude se hace en esta sesión cuando el dato o la autorización esté disponible.
A4: # | B4: Tarea | C4: Responsable | D4: Detalle paso a paso | E4: Depende de | F4: Prioridad | G4: Estado | H4: Notas
A5: 1 | B5: Decidir el marcado «Product» de las fichas | C5: Cliente | D5: Search Console marca error «falta offers» porque no hay precios. Opciones: (1) dejarlo, (2) quitar el marcado Product, (3) publicar precios de referencia reales. | E5: Respuesta del cliente | F5: Media | G5: Pendiente
A6: 2 | B6: Crear la clave de Web3Forms | C6: Cliente | D6: En web3forms.com crear la clave con el correo de contacto, restringirla a agsupply.com.do y cargarla como secreto NEXT_PUBLIC_WEB3FORMS_KEY en GitHub (Settings → Secrets → Actions). Sin ella el formulario abre el correo del visitante. | E6: Correo de contacto definitivo | F6: Alta | G6: Pendiente
A7: 3 | B7: Crear propiedad de Google Analytics 4 | C7: Cliente | D7: Crear la propiedad, copiar el ID de medición G-XXXXXXXXXX y entregarlo. Con él se activa la medición (ya está programada y apagada). | E7: Política de privacidad | F7: Media | G7: Pendiente
A8: 4 | B8: Cargar el ID de Analytics en el despliegue | C8: Claude | D8: Añadir NEXT_PUBLIC_ANALYTICS_ID al workflow de despliegue, volver a construir y comprobar en DebugView que llegan los eventos. Marcar como eventos clave: quote_whatsapp_send, contact_submit, whatsapp_click. | E8: ID de GA4 | F8: Media | G8: Pendiente
A9: 5 | B9: Página de política de privacidad | C9: Claude + Cliente | D9: Claude la redacta con los datos de la hoja 5; el cliente la aprueba. Debe publicarse antes de activar Analytics. | E9: Datos de la hoja 5 | F9: Alta | G9: Pendiente
A10: 6 | B10: Search Console: enviar el sitemap | C10: Cliente | D10: Indexación → Sitemaps → añadir sitemap.xml. Debe mostrar «Correcto» y unas 258 URLs. | E10: Propiedad verificada (hecho) | F10: Alta | G10: Pendiente
A11: 7 | B11: Search Console: solicitar indexación | C11: Cliente | D11: Inspección de URL + «Solicitar indexación» en /, /productos/, /en/, /en/products/, /productos/cuberteria/ y una ficha con foto. No en las fichas noindex. | E11: Sitemap enviado | F11: Alta | G11: Pendiente
A12: 8 | B12: Search Console: revisar a 1-2 semanas | C12: Cliente | D12: Páginas (indexadas vs excluidas; las 55 fichas delgadas aparecerán como «Excluida por noindex»), Core Web Vitals y Rendimiento. | E12: 1-2 semanas desde el despliegue | F12: Media | G12: Pendiente
A13: 9 | B13: Perfil de Empresa de Google (Maps) | C13: Cliente | D13: Crear o reclamar el perfil de AG Supply en Las Palomas, Santiago, con teléfono, horario, categoría y web. Verificarlo con el método que pida Google. Debe coincidir con los datos de la web. | E13: Dirección y horario confirmados (hoja 5) | F13: Alta | G13: Pendiente
A14: 10 | B14: Desactivar la vista previa en GitHub Pages | C14: Cliente (dueño del repositorio) | D14: Settings → Pages → desactivar, para que no quede un duplicado de la web en agsupplytic.github.io. | E14: Ninguno | F14: Media | G14: Pendiente
A15: 11 | B15: Activar FTPS en Hostinger | C15: Claude + Cliente | D15: El despliegue usa FTP; Hostinger permite FTPS. Probar en una rama antes de cambiar el workflow (protocol: ftps). | E15: Ninguno | F15: Baja | G15: Pendiente
A16: 12 | B16: Activar HSTS | C16: Claude + Cliente | D16: Agregar Strict-Transport-Security solo cuando todo el dominio (incluidos subdominios que se usen) responda por HTTPS. Difícil de revertir. | E16: Confirmar subdominios en uso | F16: Baja | G16: Pendiente
... A20: 16 | B20: Mantenimiento de redirecciones | C20: Claude | D20: 37 productos cambiaron de URL con redirección 301. Revisar en Search Console que no aparezcan errores 404 en 2-4 semanas. | E20: Indexación → Páginas | F20: Baja | G20: Pendiente
